Workbook

Sheet products
A1: 품목코드(이카운트) | B1: 바코드(SKU) | C1: 바코드(INN) | D1: 바코드(카톤) | E1: 품목명(이카운트) | F1: 상태 | G1: 판매처 | H1: 판매처관리코드 | I1: 판매처 품목명 | J1: 판매처구분 | K1: 규격 | L1: 구매처 | M1: 수급형태 | N1: 발주부서 | O1: 발주담당자 | P1: 구매처 품목코드 | Q1: 구매처 품목명 | R1: 창고그룹(이카운트) | S1: 사용창고 | T1: 구분 | U1: 카테고리
A2: 8809057631012 | B2: 8809057631012 | C2: 18809057631019 | E2: 큐플래시3기능무드라이트 | F2: 판매중 | G2: 이마트 | J2: 단일 | M2: 무역(수입) | N2: 글로벌소싱부 | R2: 유통사업부 | S2: 유통사업부, 아세로직스 | T2: [상품]
A3: 8809057631029 | B3: 8809057631029 | C3: 18809057631026 | E3: 큐플래시2기능다용도작업등 | F3: 판매중 | G3: 이마트 | J3: 단일 | L3: NINGBO FLASH I&E CO., LTD | M3: 무역(수입) | N3: 글로벌소싱부 | R3: 유통사업부 | S3: 유통사업부, 아세로직스 | T3: [상품]
A4: 8809057631043 | B4: 8809057631043 | C4: 18809057631040 | E4: 큐플래시2기능캠핑라이트 | F4: 판매중 | G4: 이마트 | J4: 단일 | L4: NINGBO FLASH I&E CO., LTD | M4: 무역(수입) | N4: 글로벌소싱부 | R4: 유통사업부 | S4: 유통사업부, 아세로직스 | T4: [상품]
A5: 8809057632101 | B5: 8809057632101 | C5: 18809057632108 | E5: TSP/케이블타이3종세트 | F5: 판매중 | G5: 이마트 | H5: 8809057632101 | I5: 다용도 케이블타이 3종세트 | J5: 단일 | K5: 2.5/3.6/4.8mm75P | L5: ANHUI TAIKONG PLASTIC INDUSTRY CO., LTD | M5: 무역(수입) | N5: 글로벌소싱부 | R5: 유통사업부 | S5: 유통사업부, 아세로직스 | T5: [상품]
A6: 8809057632118 | B6: 8809057632118 | C6: 18809057632115 | E6: TSP/릴리서블케이블타이2종세트 [3.6／4.8mm] | F6: 판매중 | G6: 이마트 | H6: 8809057632118 | I6: 릴리서블 케이블타이 2종세트 | J6: 단일 | K6: 3.6／4.8mm | L6: SHANGHAI NEW CENTURY MACHINERY CO., LTD | M6: 무역(수입) | N6: 글로벌소싱부 | R6: 유통사업부 | S6: 유통사업부, 아세로직스 | T6: [상품]
A7: H8809057638615 | B7: 8809057638615 | C7: 18809057638612 | E7: H/전공양용드라이버2종세트 | F7: 판매중 | G7: 이마트 | J7: 단일 | L7: NINGBO ZENMY IMP AND EXP CO., LTD | M7: 무역(수입) | N7: 글로벌소싱부 | R7: 유통사업부 | S7: 유통사업부, 아세로직스 | T7: [상품]
A8: H8809057638714 | B8: 8809057638714 | C8: 18809057638711 | E8: H/러버줄자10m | F8: 판매중 | G8: 이마트 | J8: 단일 | L8: HENAN YADONG MEASURING TOOLS CO., LTD | M8: 무역(수입) | N8: 글로벌소싱부 | R8: 유통사업부 | S8: 유통사업부, 아세로직스 | T8: [상품]
A9: 2018121000001 | B9: 8809057638882 | C9: 18809057638889 | E9: EMA/필수공구12종세트 | F9: 판매중 | G9: 이마트 | J9: 단일 | L9: WENZHOU ZHONGSHENG HARDWARE CO., LTD | M9: 무역(수입) | N9: 글로벌소싱부 | R9: 유통사업부 | S9: 유통사업부, 아세로직스 | T9: [상품]
A10: 2018121000002 | B10: 8809057638899 | C10: 18809057638896 | E10: EMA/필수철물10종세트 | F10: 판매중 | G10: 이마트 | J10: 단일 | L10: WENZHOU ZHONGSHENG HARDWARE CO., LTD | M10: 무역(수입) | N10: 글로벌소싱부 | R10: 유통사업부 | S10: 유통사업부, 아세로직스 | T10: [상품]
A11: 8809057638929 | B11: 8809057638929 | C11: 18809057638926 | E11: EMA/플렉시블정밀드라이버세트12in1 | F11: 판매중 | G11: 이마트 | J11: 단일 | M11: 무역(수입) | N11: 글로벌소싱부 | R11: 유통사업부 | S11: 유통사업부, 아세로직스 | T11: [상품]
A12: 8809057638943 | B12: 8809057638943 | C12: 18809057638940 | E12: EMA/미니포켓드라이버 | F12: 판매중 | G12: 이마트 | J12: 단일 | M12: 무역(수입) | N12: 글로벌소싱부 | R12: 유통사업부 | S12: 유통사업부, 아세로직스 | T12: [상품]
A13: 2020072000001 | B13: 8809057405125 | C13: 18809057405122 | E13: TP/하이홈 간편작업용 홈실리콘 투명 | F13: 판매중 | G13: 이마트 | H13: 8809057405125 | I13: 하이홈 일반용(투명) 80ml | J13: 단일 | K13: 80ml | L13: 주식회사 탑씰 | M13: 국내사입 | R13: 유통사업부 | S13: 유통사업부, 아세로직스 | T13: [상품]
A14: 2020072000002 | B14: 8809057405132 | C14: 18809057405139 | E14: TP/하이홈 욕실주방용 홈실리콘 백색 | F14: 판매중 | G14: 이마트 | J14: 단일 | K14: 100ml | L14: 주식회사 탑씰 | M14: 국내사입 | R14: 유통사업부 | S14: 유통사업부, 아세로직스 | T14: [상품]
A15: 2020072000004 | B15: 8809057405149 | C15: 18809057405146 | E15: TP/하이홈 욕실주방용 홈실리콘 투명 | F15: 판매중 | G15: 이마트 | J15: 단일 | K15: 100ml | L15: 주식회사 탑씰 | M15: 국내사입 | R15: 유통사업부 | S15: 유통사업부, 아세로직스 | T15: [상품]
A16: 2019070500005 | B16: 8809599840422 | C16: 18809599840429 | E16: 제로나인고무망치 | F16: 판매중 | G16: 이마트 | J16: 단일 | K16: 338g | L16: ZHEJIANG YONGKANG JIANLI TOOLS CO., LTD | M16: 무역(수입) | N16: 글로벌소싱부 | R16: 유통사업부 | S16: 유통사업부, 아세로직스 | T16: [상품]
A17: 2020072000003 | B17: 8809057405118 | C17: 18809057405115 | E17: TP/하이홈 간편작업용 홈실리콘 백색 | F17: 판매중 | G17: 이마트 | H17: 8809057405118 | I17: 하이홈 일반용(백색) 80ml | J17: 단일 | K17: 80ml | L17: 주식회사 탑씰 | M17: 국내사입 | R17: 유통사업부 | S17: 유통사업부, 아세로직스 | T17: [상품]
A18: 2019070500001 | B18: 8809599840385 | C18: 18809599840382 | E18: 제로나인에르고노믹펜치205mm | F18: 판매중 | G18: 이마트 | H18: 8809599840385 | I18: 제로나인펜치 205MM | J18: 단일 | K18: 205mm | L18: NINGBO ZENMY IMP AND EXP CO., LTD | M18: 무역(수입) | N18: 글로벌소싱부 | R18: 유통사업부 | S18: 유통사업부, 아세로직스 | T18: [상품]
A19: 2019070500002 | B19: 8809599840392 | C19: 18809599840399 | E19: 제로나인에르고노믹니퍼185mm | F19: 판매중 | G19: 이마트 | H19: 8809599840392 | I19: 제로나인니퍼 185MM | J19: 단일 | K19: 185mm | L19: NINGBO ZENMY IMP AND EXP CO., LTD | M19: 무역(수입) | N19: 글로벌소싱부 | R19: 유통사업부 | S19: 유통사업부, 아세로직스 | T19: [상품]
A20: 2019070500003 | B20: 8809599840408 | C20: 18809599840405 | E20: 제로나인에르고노믹롱노우즈185mm | F20: 판매중 | G20: 이마트 | H20: 8809599840408 | I20: 제로나인롱노우즈 185MM | J20: 단일 | K20: 185mm | L20: NINGBO ZENMY IMP AND EXP CO., LTD | M20: 무역(수입) | N20: 글로벌소싱부 | R20: 유통사업부 | S20: 유통사업부, 아세로직스 | T20: [상품]
A21: 2019070500004 | B21: 8809599840415 | C21: 18809599840412 | E21: 제로나인스틸망치 8OZ | F21: 판매중 | G21: 이마트 | H21: 8809599840415 | I21: 제로나인 스틸 망치 | J21: 단일 | K21: 8OZ | L21: LINYI HUACHUAN IMPORT AND EXPORT CO., LTD | M21: 무역(수입) | N21: 글로벌소싱부 | R21: 유통사업부 | S21: 유통사업부, 아세로직스 | T21: [상품]
A22: 2019070500006 | B22: 8809599840439 | C22: 18809599840436 | E22: 제로나인논슬립양용드라이버118mm | F22: 판매중 | G22: 이마트 | H22: 8809599840439 | I22: 제로나인 논슬립 양용 드라이버 | J22: 단일 | K22: 118mm | L22: SHANGQIU KEMING INDUSTRIAL AND MEASURING TOOLS CO. | M22: 무역(수입) | N22: 글로벌소싱부 | R22: 유통사업부 | S22: 유통사업부, 아세로직스 | T22: [상품]
A23: 2020041400015 | B23: 8809599840897 | C23: 18809599840897 | E23: 제로나인전선정리스테플20p | F23: 판매중 | G23: 이마트 | H23: 8809599840897 | I23: 제로나인 전선정리 스테플 20P | J23: 단일 | K23: 17mm | L23: WENZHOU ZHONGSHENG HARDWARE CO., LTD | M23: 무역(수입) | N23: 글로벌소싱부 | R23: 유통사업부 | S23: 유통사업부, 아세로직스 | T23: [제품]
A24: 2020041400010 | B24: 8809599840842 | C24: 18809599840842 | E24: 제로나인석고보드용못30mm(25p) | F24: 판매중 | G24: 이마트 | H24: 8809599840842 | I24: 제로나인 석고보드용 못 25P - 30mm | J24: 단일 | K24: 3.5*30mm | L24: WENZHOU ZHONGSHENG HARDWARE CO., LTD | M24: 무역(수입) | N24: 글로벌소싱부 | R24: 유통사업부 | S24: 유통사업부, 아세로직스 | T24: [제품]
A25: 2020041400011 | B25: 8809599840859 | C25: 18809599840859 | E25: 제로나인콘크리트못38mm(25p) | F25: 판매중 | G25: 이마트 | H25: 8809599840859 | I25: 제로나인 콘크리트못 25P - 38mm | J25: 단일 | K25: 38mm | L25: WENZHOU ZHONGSHENG HARDWARE CO., LTD | M25: 무역(수입) | N25: 글로벌소싱부 | R25: 유통사업부 | S25: 유통사업부, 아세로직스 | T25: [상품]
A26: 2020041400012 | B26: 8809599840866 | C26: 18809599840866 | E26: 제로나인콘크리트못50mm(25p) | F26: 판매중 | G26: 이마트 | J26: 단일 | K26: 50mm | L26: WENZHOU ZHONGSHENG HARDWARE CO., LTD | M26: 무역(수입) | N26: 글로벌소싱부 | R26: 유통사업부 | S26: 유통사업부, 아세로직스 | T26: [상품]
A27: 2020041400013 | B27: 8809599840873 | C27: 18809599840873 | E27: 제로나인스테인레스못20mm(25p) | F27: 판매중 | G27: 이마트 | H27: 8809599840873 | I27: 제로나인 스텐레스못 25P - 20mm | J27: 단일 | K27: 3.5*20mm | L27: WENZHOU ZHONGSHENG HARDWARE CO., LTD | M27: 무역(수입) | N27: 글로벌소싱부 | R27: 유통사업부 | S27: 유통사업부, 아세로직스 | T27: [제품]
A28: 2020041400014 | B28: 8809599840880 | C28: 18809599840880 | E28: 제로나인타격앙카12PC | F28: 판매중 | G28: 이마트 | H28: 8809599840880 | I28: 제로나인 타격 앙카 12P - 5mm | J28: 단일 | K28: 5mm | L28: WENZHOU ZHONGSHENG HARDWARE CO., LTD | M28: 무역(수입) | N28: 글로벌소싱부 | R28: 유통사업부 | S28: 유통사업부, 아세로직스 | T28: [제품]
A29: 2020041400016 | B29: 8809599840903 | C29: 18809599840903 | E29: 제로나인전선정리마운트15p | F29: 판매중 | G29: 이마트 | J29: 단일 | K29: 20*20mm | L29: WENZHOU ZHONGSHENG HARDWARE CO., LTD | M29: 무역(수입) | N29: 글로벌소싱부 | R29: 유통사업부 | S29: 유통사업부, 아세로직스 | T29: [제품]
A30: 2020041400017 | B30: 8809599840910 | C30: 18809599840910 | E30: 제로나인칼블럭7mm(25p) | F30: 판매중 | G30: 이마트 | J30: 단일 | K30: 7mm | L30: WENZHOU ZHONGSHENG HARDWARE CO., LTD | M30: 무역(수입) | N30: 글로벌소싱부 | R30: 유통사업부 | S30: 유통사업부, 아세로직스 | T30: [반제품]
A31: 2020041400018 | B31: 8809599840927 | C31: 18809599840927 | E31: 제로나인심플선반다보12p | F31: 판매중 | G31: 이마트 | H31: 8809599840927 | I31: 제로나인 심플 선반다보 12P | J31: 단일 | K31: 4mm | L31: WENZHOU ZHONGSHENG HARDWARE CO., LTD | M31: 무역(수입) | N31: 글로벌소싱부 | R31: 유통사업부 | S31: 유통사업부, 아세로직스 | T31: [반제품]
A32: 2020051500001 | B32: 8809599840934 | C32: 18809599840931 | E32: 제로나인와이어액자걸이 | F32: 판매중 | G32: 이마트 | J32: 단일 | K32: 108cm | L32: NINGBO SOURCE E-BUSINESS CO., LTD | M32: 무역(수입) | N32: 글로벌소싱부 | R32: 유통사업부 | S32: 유통사업부, 아세로직스 | T32: [상품]
A33: 2020120700001 | B33: 8809599840972 | C33: 18809599840979 | E33: 제로나인글루건세트 | F33: 판매중 | G33: 이마트 | J33: 단일 | K33: 40W/10P | L33: NINGBO KINGVOS ELECTRICAL APPLIANCE CO., LTD | M33: 무역(수입) | N33: 글로벌소싱부 | R33: 유통사업부 | S33: 유통사업부, 아세로직스 | T33: [상품]
A34: 2020051500002 | B34: 8809599840736 | C34: 18809599840733 | E34: 제로나인다용도S자고리3p(대) | F34: 판매중 | G34: 이마트 | H34: 8809599840736 | I34: 제로나인 S자 고리 90mm 3P | J34: 단일 | K34: 9cm | L34: NINGBO SOURCE E-BUSINESS CO., LTD | M34: 무역(수입) | N34: 글로벌소싱부 | R34: 유통사업부 | S34: 유통사업부, 아세로직스 | T34: [상품]
A35: 2019100200001 | B35: 8809599840583 | C35: 18809599840580 | E35: 제로나인멍키파이프렌치세트 | F35: 판매중 | G35: 이마트 | J35: 단일 | K35: 46P SET | L35: NINGBO LIXIN TOOLS CO., LTD | M35: 무역(수입) | N35: 글로벌소싱부 | R35: 유통사업부 | S35: 유통사업부, 아세로직스 | T35: [상품]
A36: 2019082900002 | B36: 8809599840613 | C36: 18809599840610 | E36: 제로나인각도조절라쳇드라이버 | F36: 판매중 | G36: 이마트 | H36: 8809599840613 | I36: 제로나인 각도조절 라쳇 드라이버 | J36: 단일 | K36: 12in1 | M36: 무역(수입) | N36: 글로벌소싱부 | R36: 유통사업부 | S36: 유통사업부, 아세로직스 | T36: [상품]
A37: 2019082900001 | B37: 8809599840620 | C37: 18809599840627 | E37: 제로나인다용도소켓드라이버 | F37: 판매중 | G37: 이마트 | J37: 단일 | K37: 21in1 | L37: HANGZHOU SHENGDEYI PLASTIC AND ELETROMECHANICAL CO., LTD | M37: 무역(수입) | N37: 글로벌소싱부 | R37: 유통사업부 | S37: 유통사업부, 아세로직스 | T37: [상품]
A38: 2020051500003 | B38: 8809599840743 | C38: 18809599840740 | E38: 제로나인다용도S자고리5p(소) | F38: 판매중 | G38: 이마트 | H38: 8809599840743 | I38: 제로나인 S자 고리 70mm 5P | J38: 단일 | K38: 7cm | L38: NINGBO SOURCE E-BUSINESS CO., LTD | M38: 무역(수입) | N38: 글로벌소싱부 | R38: 유통사업부 | S38: 유통사업부, 아세로직스 | T38: [상품]
A39: 2020041400001 | B39: 8809599840750 | C39: 18809599840750 | E39: 제로나인액자걸이2p | F39: 판매중 | G39: 이마트 | J39: 단일 | K39: 40mm | L39: WENZHOU ZHONGSHENG HARDWARE CO., LTD | M39: 무역(수입) | N39: 글로벌소싱부 | R39: 유통사업부 | S39: 유통사업부, 아세로직스 | T39: [상품]
A40: 2020041400002 | B40: 8809599840767 | C40: 18809599840767 | E40: 제로나인걸고리 | F40: 판매중 | G40: 이마트 | J40: 단일 | K40: 75mm | L40: WENZHOU ZHONGSHENG HARDWARE CO., LTD | M40: 무역(수입) | N40: 글로벌소싱부 | R40: 유통사업부 | S40: 유통사업부, 아세로직스 | T40: [상품]
...

Sheet Sheet1
A1: 거래처 | B1: 상품코드 | C1: 이카운트코드 | D1: 업체등록 상품명 | E1: 주문서 상품명 | F1: 일치여부 | G1: 업태상품조회 | H1: 광교점
A2: 이마트 | B2: 8809057631012 | C2: 8809057631012 | D2: Q플래쉬 3기능 무드 라이트 | E2: =VLOOKUP(B:B,주문서!A:B,2,0) -> #N/A | F2: =IF(D2=E2, "✅", "❌") -> #N/A | G2: =VLOOKUP(B:B,[1]업태상품목록!$B:$C,2,0) -> Q플래쉬 3기능 무드 라이트 | H2: =VLOOKUP(B:B,[2]점포상품목록!$D:$E,2,0) -> Q플래쉬 3기능 무드 라이트
A3: 이마트 | B3: 8809057631029 | C3: 8809057631029 | D3: 2기능 다용도 작업등 | E3: =VLOOKUP(B:B,주문서!A:B,2,0) -> #N/A | F3: =IF(D3=E3, "✅", "❌") -> #N/A | G3: =VLOOKUP(B:B,[1]업태상품목록!$B:$C,2,0) -> 2기능 다용도 작업등 | H3: =VLOOKUP(B:B,[2]점포상품목록!$D:$E,2,0) -> #N/A
A4: 이마트 | B4: 8809057631043 | C4: 8809057631043 | D4: 2기능 캠핑라이트 | E4: =VLOOKUP(B:B,주문서!A:B,2,0) -> #N/A | F4: =IF(D4=E4, "✅", "❌") -> #N/A | G4: =VLOOKUP(B:B,[1]업태상품목록!$B:$C,2,0) -> 2기능 캠핑라이트 | H4: =VLOOKUP(B:B,[2]점포상품목록!$D:$E,2,0) -> #N/A
A5: 이마트 | B5: 8809057632101 | C5: 8809057632101 | D5: 다용도 케이블타이 3종세트 | E5: =VLOOKUP(B:B,주문서!A:B,2,0) -> 다용도 케이블타이 3종세트 | F5: =IF(D5=E5, "✅", "❌") -> ✅ | G5: =VLOOKUP(B:B,[1]업태상품목록!$B:$C,2,0) -> 케이블타이3종세트 | H5: =VLOOKUP(B:B,[2]점포상품목록!$D:$E,2,0) -> 케이블타이3종세트
A6: 이마트 | B6: 8809057632118 | C6: 8809057632118 | D6: 릴리서블 케이블타이 2종세트 | E6: =VLOOKUP(B:B,주문서!A:B,2,0) -> 릴리서블 케이블타이 2종세트 | F6: =IF(D6=E6, "✅", "❌") -> ✅ | G6: =VLOOKUP(B:B,[1]업태상품목록!$B:$C,2,0) -> 릴리서블 케이블타이 2종세트 | H6: =VLOOKUP(B:B,[2]점포상품목록!$D:$E,2,0) -> 릴리서블 케이블타이 2종세트
A7: 이마트 | B7: 8809057638615 | C7: H8809057638615 | D7: 전공 양용 드라이버 2종 세트 | E7: =VLOOKUP(B:B,주문서!A:B,2,0) -> #N/A | F7: =IF(D7=E7, "✅", "❌") -> #N/A | G7: =VLOOKUP(B:B,[1]업태상품목록!$B:$C,2,0) -> 전공 양용 드라이버 2종 세트 | H7: =VLOOKUP(B:B,[2]점포상품목록!$D:$E,2,0) -> 전공 양용 드라이버 2종 세트
A8: 이마트 | B8: 8809057638714 | C8: H8809057638714 | D8: COMAX 러버 줄자10M | E8: =VLOOKUP(B:B,주문서!A:B,2,0) -> #N/A | F8: =IF(D8=E8, "✅", "❌") -> #N/A | G8: =VLOOKUP(B:B,[1]업태상품목록!$B:$C,2,0) -> COMAX 러버 줄자10M | H8: =VLOOKUP(B:B,[2]점포상품목록!$D:$E,2,0) -> COMAX 러버 줄자10M
A9: 이마트 | B9: 8809057638882 | C9: 2018121000001 | D9: 필수공구 12종세트 | E9: =VLOOKUP(B:B,주문서!A:B,2,0) -> #N/A | F9: =IF(D9=E9, "✅", "❌") -> #N/A | G9: =VLOOKUP(B:B,[1]업태상품목록!$B:$C,2,0) -> 필수공구 12종세트 | H9: =VLOOKUP(B:B,[2]점포상품목록!$D:$E,2,0) -> 필수공구 12종세트
A10: 이마트 | B10: 8809057638899 | C10: 2018121000002 | D10: 필수철물 10종세트 | E10: =VLOOKUP(B:B,주문서!A:B,2,0) -> #N/A | F10: =IF(D10=E10, "✅", "❌") -> #N/A | G10: =VLOOKUP(B:B,[1]업태상품목록!$B:$C,2,0) -> 필수철물 10종세트 | H10: =VLOOKUP(B:B,[2]점포상품목록!$D:$E,2,0) -> 필수철물 10종세트
A11: 이마트 | B11: 8809057638929 | C11: 8809057638929 | D11: 플렉시블드라이버세트 | E11: =VLOOKUP(B:B,주문서!A:B,2,0) -> #N/A | F11: =IF(D11=E11, "✅", "❌") -> #N/A | G11: =VLOOKUP(B:B,[1]업태상품목록!$B:$C,2,0) -> 플렉시블드라이버세트 | H11: =VLOOKUP(B:B,[2]점포상품목록!$D:$E,2,0) -> #N/A
A12: 이마트 | B12: 8809057638943 | C12: 8809057638943 | D12: 미니 포켓 드라이버 | E12: =VLOOKUP(B:B,주문서!A:B,2,0) -> #N/A | F12: =IF(D12=E12, "✅", "❌") -> #N/A | G12: =VLOOKUP(B:B,[1]업태상품목록!$B:$C,2,0) -> 미니 포켓 드라이버 | H12: =VLOOKUP(B:B,[2]점포상품목록!$D:$E,2,0) -> #N/A
A13: 이마트 | B13: 8809057405125 | C13: 2020072000001 | D13: 하이홈 일반용(투명) 80ml | E13: =VLOOKUP(B:B,주문서!A:B,2,0) -> 하이홈 일반용(투명) 80ml | F13: =IF(D13=E13, "✅", "❌") -> ✅ | G13: =VLOOKUP(B:B,[1]업태상품목록!$B:$C,2,0) -> 하이홈 일반용(투명) 80ml | H13: =VLOOKUP(B:B,[2]점포상품목록!$D:$E,2,0) -> 하이홈 일반용(투명) 80ml
A14: 이마트 | B14: 8809057405132 | C14: 2020072000002 | D14: 하이홈 욕실용(백색) 100ml | E14: =VLOOKUP(B:B,주문서!A:B,2,0) -> #N/A | F14: =IF(D14=E14, "✅", "❌") -> #N/A | G14: =VLOOKUP(B:B,[1]업태상품목록!$B:$C,2,0) -> 하이홈 욕실용(백색) 100ml | H14: =VLOOKUP(B:B,[2]점포상품목록!$D:$E,2,0) -> 하이홈 욕실용(백색) 100ml
A15: 이마트 | B15: 8809057405149 | C15: 2020072000004 | D15: 하이홈 욕실용(투명) 100ml | E15: =VLOOKUP(B:B,주문서!A:B,2,0) -> #N/A | F15: =IF(D15=E15, "✅", "❌") -> #N/A | G15: =VLOOKUP(B:B,[1]업태상품목록!$B:$C,2,0) -> 하이홈 욕실용(투명) 100ml | H15: =VLOOKUP(B:B,[2]점포상품목록!$D:$E,2,0) -> 하이홈 욕실용(투명) 100ml
A16: 이마트 | B16: 8809599840422 | C16: 2019070500005 | D16: 제로나인 고무망치 | E16: =VLOOKUP(B:B,주문서!A:B,2,0) -> #N/A | F16: =IF(D16=E16, "✅", "❌") -> #N/A | G16: =VLOOKUP(B:B,[1]업태상품목록!$B:$C,2,0) -> 제로나인 고무망치 | H16: =VLOOKUP(B:B,[2]점포상품목록!$D:$E,2,0) -> 제로나인 고무망치
A17: 이마트 | B17: 8809057405118 | C17: 2020072000003 | D17: 하이홈 일반용(백색) 80ml | E17: =VLOOKUP(B:B,주문서!A:B,2,0) -> 하이홈 일반용(백색) 80ml | F17: =IF(D17=E17, "✅", "❌") -> ✅ | G17: =VLOOKUP(B:B,[1]업태상품목록!$B:$C,2,0) -> 하이홈 일반용(백색) 80ml | H17: =VLOOKUP(B:B,[2]점포상품목록!$D:$E,2,0) -> 하이홈 일반용(백색) 80ml
A18: 이마트 | B18: 8809599840385 | C18: 2019070500001 | D18: 제로나인펜치 205MM | E18: =VLOOKUP(B:B,주문서!A:B,2,0) -> 제로나인펜치 205MM | F18: =IF(D18=E18, "✅", "❌") -> ✅ | G18: =VLOOKUP(B:B,[1]업태상품목록!$B:$C,2,0) -> 제로나인펜치 205MM | H18: =VLOOKUP(B:B,[2]점포상품목록!$D:$E,2,0) -> 제로나인펜치 205MM
A19: 이마트 | B19: 8809599840392 | C19: 2019070500002 | D19: 제로나인니퍼 185MM | E19: =VLOOKUP(B:B,주문서!A:B,2,0) -> 제로나인니퍼 185MM | F19: =IF(D19=E19, "✅", "❌") -> ✅ | G19: =VLOOKUP(B:B,[1]업태상품목록!$B:$C,2,0) -> 제로나인니퍼 185MM | H19: =VLOOKUP(B:B,[2]점포상품목록!$D:$E,2,0) -> 제로나인니퍼 185MM
A20: 이마트 | B20: 8809599840408 | C20: 2019070500003 | D20: 제로나인롱노우즈 185MM | E20: =VLOOKUP(B:B,주문서!A:B,2,0) -> 제로나인롱노우즈 185MM | F20: =IF(D20=E20, "✅", "❌") -> ✅ | G20: =VLOOKUP(B:B,[1]업태상품목록!$B:$C,2,0) -> 제로나인롱노우즈 185MM | H20: =VLOOKUP(B:B,[2]점포상품목록!$D:$E,2,0) -> 제로나인롱노우즈 185MM
... A107: 이마트 | B107: 8809148128575 | C107: 8809148128575 | D107: 콘센트타이머 슬림형 | E107: =VLOOKUP(B:B,주문서!A:B,2,0) -> 콘센트타이머 슬림형 | F107: =IF(D107=E107, "✅", "❌") -> ✅ | G107: =VLOOKUP(B:B,[1]업태상품목록!$B:$C,2,0) -> 콘센트타이머 슬림형 | H107: =VLOOKUP(B:B,[2]점포상품목록!$D:$E,2,0) -> 콘센트타이머 슬림형
A108: 이마트 | B108: 8809148123051 | C108: 8809148123051-1 | D108: 하이홈 접착식 드라이기걸이 플렉시블형 | E108: =VLOOKUP(B:B,주문서!A:B,2,0) -> 하이홈 접착식 드라이기걸이 플렉시블형 | F108: =IF(D108=E108, "✅", "❌") -> ✅ | G108: =VLOOKUP(B:B,[1]업태상품목록!$B:$C,2,0) -> 하이홈 접착식 드라이기걸이 플렉시블형 | H108: =VLOOKUP(B:B,[2]점포상품목록!$D:$E,2,0) -> 하이홈 접착식 드라이기걸이 플렉시블형
A109: 이마트 | B109: 8809148123075 | C109: 8809148123075 | D109: 하이홈 접착식 드라이기선반 | E109: =VLOOKUP(B:B,주문서!A:B,2,0) -> 하이홈 접착식 드라이기선반 | F109: =IF(D109=E109, "✅", "❌") -> ✅ | G109: =VLOOKUP(B:B,[1]업태상품목록!$B:$C,2,0) -> 하이홈 접착식 드라이기선반 | H109: =VLOOKUP(B:B,[2]점포상품목록!$D:$E,2,0) -> 하이홈 접착식 드라이기선반
A110: 이마트 | B110: 8809148123082 | C110: 8809148123082-1 | D110: 하이홈 접착식 후크 고리형 | E110: =VLOOKUP(B:B,주문서!A:B,2,0) -> 하이홈 접착식 후크 고리형 | F110: =IF(D110=E110, "✅", "❌") -> ✅ | G110: =VLOOKUP(B:B,[1]업태상품목록!$B:$C,2,0) -> 하이홈 접착식 후크 고리형 | H110: =VLOOKUP(B:B,[2]점포상품목록!$D:$E,2,0) -> 하이홈 접착식 후크 고리형
A111: 이마트 | B111: 8809057636031 | C111: 2024111300003 | D111: 큐플래시 와이어 클립 북라이트 | E111: =VLOOKUP(B:B,주문서!A:B,2,0) -> #N/A | F111: =IF(D111=E111, "✅", "❌") -> #N/A | G111: =VLOOKUP(B:B,[1]업태상품목록!$B:$C,2,0) -> 큐플래시 와이어 클립 북라이트 | H111: =VLOOKUP(B:B,[2]점포상품목록!$D:$E,2,0) -> 큐플래시 와이어 클립 북라이트
A112: 이마트 | B112: 8809148128599 | C112: 2023121900016 | D112: 라이너스 개별멀티탭 3구 2.5M_베이지 | E112: =VLOOKUP(B:B,주문서!A:B,2,0) -> 라이너스 개별멀티탭 3구 2.5M_베이지 | F112: =IF(D112=E112, "✅", "❌") -> ✅ | G112: =VLOOKUP(B:B,[1]업태상품목록!$B:$C,2,0) -> 라이너스 개별멀티탭 3구 2.5M_베이지 | H112: =VLOOKUP(B:B,[2]점포상품목록!$D:$E,2,0) -> 라이너스 개별멀티탭 3구 2.5M_베이지
A113: 이마트 | B113: 8809148128629 | C113: 2023121900017 | D113: 라이너스 개별멀티탭 4구 1.5M_스카이블루 | E113: =VLOOKUP(B:B,주문서!A:B,2,0) -> 라이너스 개별멀티탭 4구 1.5M_스카이블루 | F113: =IF(D113=E113, "✅", "❌") -> ✅ | G113: =VLOOKUP(B:B,[1]업태상품목록!$B:$C,2,0) -> 라이너스 개별멀티탭 4구 1.5M_스카이블루 | H113: =VLOOKUP(B:B,[2]점포상품목록!$D:$E,2,0) -> 라이너스 개별멀티탭 4구 1.5M_스카이블루
A114: 이마트 | B114: 8809148128636 | C114: 2023121900018 | D114: 라이너스 개별멀티탭 4구 2.5M_핑크 | E114: =VLOOKUP(B:B,주문서!A:B,2,0) -> 라이너스 개별멀티탭 4구 2.5M_핑크 | F114: =IF(D114=E114, "✅", "❌") -> ✅ | G114: =VLOOKUP(B:B,[1]업태상품목록!$B:$C,2,0) -> 라이너스 개별멀티탭 4구 2.5M_핑크 | H114: =VLOOKUP(B:B,[2]점포상품목록!$D:$E,2,0) -> 라이너스 개별멀티탭 4구 2.5M_핑크
A115: 이마트 | B115: 8809599841344 | C115: 2024042300109 | D115: 몬스툴 와이어 브러시세트 | E115: =VLOOKUP(B:B,주문서!A:B,2,0) -> 몬스툴 와이어 브러시세트 | F115: =IF(D115=E115, "✅", "❌") -> ✅ | G115: =VLOOKUP(B:B,[1]업태상품목록!$B:$C,2,0) -> 몬스툴 와이어 브러시세트 | H115: =VLOOKUP(B:B,[2]점포상품목록!$D:$E,2,0) -> 몬스툴 와이어 브러시세트
A116: 이마트 | B116: 8809599841368 | C116: 2024042300111 | D116: 몬스툴 핸드샌딩 스펀지사포 | E116: =VLOOKUP(B:B,주문서!A:B,2,0) -> 몬스툴 핸드샌딩 스펀지사포 | F116: =IF(D116=E116, "✅", "❌") -> ✅ | G116: =VLOOKUP(B:B,[1]업태상품목록!$B:$C,2,0) -> 몬스툴 핸드샌딩 스펀지사포 | H116: =VLOOKUP(B:B,[2]점포상품목록!$D:$E,2,0) -> 몬스툴 핸드샌딩 스펀지사포
A117: 이마트 | B117: 8809599841092 | C117: 8809599841092 | D117: 제로나인 직결사나못 4종 | E117: =VLOOKUP(B:B,주문서!A:B,2,0) -> 제로나인 직결사나못 4종 | F117: =IF(D117=E117, "✅", "❌") -> ✅ | G117: =VLOOKUP(B:B,[1]업태상품목록!$B:$C,2,0) -> 제로나인 직결사나못 4종 | H117: =VLOOKUP(B:B,[2]점포상품목록!$D:$E,2,0) -> 제로나인 직결사나못 4종
A118: 이마트 | B118: 8809599841115 | C118: 8809599841115 | D118: 제로나인 스크류 못 4종 | E118: =VLOOKUP(B:B,주문서!A:B,2,0) -> 제로나인 스크류 못 4종 | F118: =IF(D118=E118, "✅", "❌") -> ✅ | G118: =VLOOKUP(B:B,[1]업태상품목록!$B:$C,2,0) -> 제로나인 스크류 못 4종 | H118: =VLOOKUP(B:B,[2]점포상품목록!$D:$E,2,0) -> 제로나인 스크류 못 4종
A119: 이마트 | B119: 8809599841085 | C119: 8809599841085 | D119: 제로나인 일반나사못 4종 | E119: =VLOOKUP(B:B,주문서!A:B,2,0) -> 제로나인 일반나사못 4종 | F119: =IF(D119=E119, "✅", "❌") -> ✅ | G119: =VLOOKUP(B:B,[1]업태상품목록!$B:$C,2,0) -> 제로나인 일반나사못 4종 | H119: =VLOOKUP(B:B,[2]점포상품목록!$D:$E,2,0) -> 제로나인 일반나사못 4종
A120: 이마트 | B120: 8809057405187 | C120: 2024030500002 | D120: 하이홈 욕실주방용 홈실리콘 백색 100ml | E120: =VLOOKUP(B:B,주문서!A:B,2,0) -> 하이홈 욕실주방용 홈실리콘 백색 100ml | F120: =IF(D120=E120, "✅", "❌") -> ✅ | G120: =VLOOKUP(B:B,[1]업태상품목록!$B:$C,2,0) -> 하이홈 욕실주방용 홈실리콘 백색 100ml | H120: =VLOOKUP(B:B,[2]점포상품목록!$D:$E,2,0) -> 하이홈 욕실주방용 홈실리콘 백색 100ml
A121: 이마트 | B121: 8809057405194 | C121: 2024030500001 | D121: 하이홈 욕실주방용 홈실리콘 투명 100ml | E121: =VLOOKUP(B:B,주문서!A:B,2,0) -> 하이홈 욕실주방용 홈실리콘 투명 100ml | F121: =IF(D121=E121, "✅", "❌") -> ✅ | G121: =VLOOKUP(B:B,[1]업태상품목록!$B:$C,2,0) -> 하이홈 욕실주방용 홈실리콘 투명 100ml | H121: =VLOOKUP(B:B,[2]점포상품목록!$D:$E,2,0) -> 하이홈 욕실주방용 홈실리콘 투명 100ml
A122: 이마트 | B122: 8809774029895 | C122: 2024123000001 | D122: 밸류엠 15W (QC3.0) 고속 분리형 충전기 ( | E122: =VLOOKUP(B:B,주문서!A:B,2,0) -> 밸류엠 15W (QC3.0) 고속 분리형 충전기 ( | F122: =IF(D122=E122, "✅", "❌") -> ✅ | G122: =VLOOKUP(B:B,[1]업태상품목록!$B:$C,2,0) -> 15W (QC3.0) 고속 분리형 충전기 (케이블 | H122: =VLOOKUP(B:B,[2]점포상품목록!$D:$E,2,0) -> 15W (QC3.0) 고속 분리형 충전기 (케이블
... A132: 이마트 | B132: 8809057400038 | C132: 2025041800001 | D132: 몬스툴 파워토크 충전 전동드릴12V (C타입) | E132: =VLOOKUP(B:B,주문서!A:B,2,0) -> 몬스툴 파워토크 충전 전동드릴12V (C타입) | F132: =IF(D132=E132, "✅", "❌") -> ✅ | G132: =VLOOKUP(B:B,[1]업태상품목록!$B:$C,2,0) -> 파워토크 충전 전동드릴12V (C타입) | H132: =VLOOKUP(B:B,[2]점포상품목록!$D:$E,2,0) -> 파워토크 충전 전동드릴12V (C타입)
A133: 이마트 | B133: 8809057630046 | C133: 8809057630046A | D133: 라이너스 해외여행용 어댑터 | E133: =VLOOKUP(B:B,주문서!A:B,2,0) -> 라이너스 해외여행용 어댑터 | F133: =IF(D133=E133, "✅", "❌") -> ✅ | G133: =VLOOKUP(B:B,[1]업태상품목록!$B:$C,2,0) -> 라이너스 해외여행용 어댑터 | H133: =VLOOKUP(B:B,[2]점포상품목록!$D:$E,2,0) -> 라이너스 해외여행용 어댑터
A134: 이마트 | B134: 8809057636017 | C134: 2024111300001 | D134: 알루미늄 다기능 줌 랜턴 | E134: =VLOOKUP(B:B,주문서!A:B,2,0) -> 알루미늄 다기능 줌 랜턴 | F134: =IF(D134=E134, "✅", "❌") -> ✅ | G134: =VLOOKUP(B:B,[1]업태상품목록!$B:$C,2,0) -> 알루미늄 다기능 줌 랜턴 | H134: =VLOOKUP(B:B,[2]점포상품목록!$D:$E,2,0) -> 알루미늄 다기능 줌 랜턴
A135: 이마트 | B135: 8809057636024 | C135: 2024111300002 | D135: 큐플래시 미니 캠핑 랜턴 | E135: =VLOOKUP(B:B,주문서!A:B,2,0) -> #N/A | F135: =IF(D135=E135, "✅", "❌") -> #N/A | G135: =VLOOKUP(B:B,[1]업태상품목록!$B:$C,2,0) -> 큐플래시 미니 캠핑 랜턴 | H135: =VLOOKUP(B:B,[2]점포상품목록!$D:$E,2,0) -> 큐플래시 미니 캠핑 랜턴
...

Sheet 주문서
A1: 8809599841450 | B1: 몬스툴 그립 멍키스패너 200mm
A2: 8809599840514 | B2: 제로나인다용도스크레퍼 75MM
A3: 8809057405118 | B3: 하이홈 일반용(백색) 80ml
A4: 8809599840460 | B4: 제로나인 정밀 드라이버 세트
A5: 8809599840415 | B5: 제로나인 스틸 망치
A6: 8809599840552 | B6: 제로나인 다용도가위 185MM
A7: 8809599841412 | B7: 제로나인 T14 공구함 (중)
A8: 8809774025071 | B8: Cto8 PD 20W 고속 데이터 케이블 1.2M
A9: 8809599840439 | B9: 제로나인 논슬립 양용 드라이버
A10: 8809599841115 | B10: 제로나인 스크류 못 4종
A11: 8809599840408 | B11: 제로나인롱노우즈 185MM
A12: 8809057630046 | B12: 라이너스 해외여행용 어댑터
... A2461: 8809599840545 | B2461: 제로나인 작업용커터칼 18mm
